package com.hashsoft.audiotape.core.extensions

import com.google.common.util.concurrent.ListenableFuture
import com.google.common.util.concurrent.MoreExecutors
import com.google.common.util.concurrent.Uninterruptibles
import kotlinx.coroutines.CancellableContinuation
import kotlinx.coroutines.Runnable
import kotlinx.coroutines.suspendCancellableCoroutine
import java.util.concurrent.ExecutionException
import kotlin.coroutines.resume
import kotlin.coroutines.resumeWithException

suspend fun <T> ListenableFuture<T>.await(): T {
    try {
        if (isDone) return Uninterruptibles.getUninterruptibly(this)
    } catch (e: ExecutionException) {
        // ExecutionException is the only kind of exception that can be thrown from a gotten
        // Future, other than CancellationException. Cancellation is propagated upward so that
        // the coroutine running this suspend function may process it.
        // Any other Exception showing up here indicates a very fundamental bug in a
        // Future implementation.
        throw e.nonNullCause()
    }

    return suspendCancellableCoroutine { cont: CancellableContinuation<T> ->
        addListener(
            ToContinuation(this, cont),
            MoreExecutors.directExecutor()
        )
        cont.invokeOnCancellation {
            cancel(false)
        }
    }
}

private fun ExecutionException.nonNullCause(): Throwable {
    return this.cause!!
}

private class ToContinuation<T>(
    val futureToObserve: ListenableFuture<T>,
    val continuation: CancellableContinuation<T>
) : Runnable {
    override fun run() {
        if (futureToObserve.isCancelled) {
            continuation.cancel()
        } else {
            try {
                continuation.resume(Uninterruptibles.getUninterruptibly(futureToObserve))
            } catch (e: ExecutionException) {
                // ExecutionException is the only kind of exception that can be thrown from a gotten
                // Future. Anything else showing up here indicates a very fundamental bug in a
                // Future implementation.
                continuation.resumeWithException(e.nonNullCause())
            }
        }
    }
}